<?xml version="1.0" encoding="utf-8"?>
<!-- This URDF was automatically created by SolidWorks to URDF Exporter! Originally created by Stephen Brawner (brawner@gmail.com) 
     Commit Version: 1.6.0-4-g7f85cfe  Build Version: 1.6.7995.38578
     For more information, please see http://wiki.ros.org/sw_urdf_exporter -->
<robot
  name="Dora2">
  <link
    name="base_link">
    <inertial>
      <origin
        xyz="-0.026899 -1.898E-06 0.035918"
        rpy="0 0 0" />
      <mass
        value="5.7651" />
      <inertia
        ixx="0.020053"
        ixy="-8.8171E-07"
        ixz="-3.1053E-05"
        iyy="0.014582"
        iyz="1.1072E-05"
        izz="0.013124" />
    </inertial>
    <visual>
      <origin
        xyz="0 0 0"
        rpy="0 0 0" />
      <geometry>
        <mesh
          filename="../meshes/base_link.STL" />
      </geometry>
      <material
        name="">
        <color
          rgba="0.89804 0.91765 0.92941 1" />
      </material>
    </visual>
    <!-- <collision>
      <origin
        xyz="0 0 0"
        rpy="0 0 0" />
      <geometry>
        <mesh
          filename="../meshes/base_link.STL" />
      </geometry>
    </collision> -->
    <collision>
      <origin
        xyz="0 0. 0.1"
        rpy="0 0 0" />
      <geometry>
        <box size="0.4 0.4 0.4"/>
      </geometry>
    </collision>
  </link>
  <link
    name="l_arm_shoulder_pitch_Link">
    <inertial>
      <origin
        xyz="-0.0032277 -0.00090287 0.064029"
        rpy="0 0 0" />
      <mass
        value="0.47485" />
      <inertia
        ixx="0.00026491"
        ixy="-1.493E-06"
        ixz="-1.3787E-05"
        iyy="0.00023165"
        iyz="-4.313E-06"
        izz="0.00018067" />
    </inertial>
    <visual>
      <origin
        xyz="0 0 0"
        rpy="0 0 0" />
      <geometry>
        <mesh
          filename="../meshes/l_arm_shoulder_pitch_Link.STL" />
      </geometry>
      <material
        name="">
        <color
          rgba="1 1 1 1" />
      </material>
    </visual>
    <collision>
      <origin
        xyz="0 0 0"
        rpy="0 0 0" />
      <geometry>
        <mesh
          filename="../meshes/l_arm_shoulder_pitch_Link.STL" />
      </geometry>
    </collision>
  </link>
  <joint
    name="l_arm_shoulder_pitch_joint"
    type="fixed">
    <origin
      xyz="0 0.16535 0.20168"
      rpy="-1.2217 0 0" />
    <parent
      link="base_link" />
    <child
      link="l_arm_shoulder_pitch_Link" />
    <axis
      xyz="0 0 1" />
    <limit
      lower="-2"
      upper="2"
      effort="36"
      velocity="12" />
  </joint>
  <link
    name="l_arm_shoulder_roll_Link">
    <inertial>
      <origin
        xyz="0.00482434461878539 -0.000218754304780355 -0.066684892346818"
        rpy="0 0 0" />
      <mass
        value="0.369997353872883" />
      <inertia
        ixx="0.000197558683212289"
        ixy="-1.5602634042867E-06"
        ixz="-2.63403084055417E-05"
        iyy="0.00020014685176238"
        iyz="-3.03976144077389E-06"
        izz="0.000160207650697516" />
    </inertial>
    <visual>
      <origin
        xyz="0 0 0"
        rpy="0 0 0" />
      <geometry>
        <mesh
          filename="../meshes/l_arm_shoulder_roll_Link.STL" />
      </geometry>
      <material
        name="">
        <color
          rgba="1 1 1 1" />
      </material>
    </visual>
    <collision>
      <origin
        xyz="0 0 0"
        rpy="0 0 0" />
      <geometry>
        <mesh
          filename="../meshes/l_arm_shoulder_roll_Link.STL" />
      </geometry>
    </collision>
  </link>
  <joint
    name="l_arm_shoulder_roll_joint"
    type="fixed">
    <origin
      xyz="0 0 0.07625"
      rpy="1.2217 0 0" />
    <parent
      link="l_arm_shoulder_pitch_Link" />
    <child
      link="l_arm_shoulder_roll_Link" />
    <axis
      xyz="1 0 0" />
    <limit
      lower="0"
      upper="3"
      effort="36"
      velocity="12" />
  </joint>
  <link
    name="l_arm_shoulder_yaw_Link">
    <inertial>
      <origin
        xyz="-4.03282683863471E-05 0.00245809993860069 -0.0964013469128064"
        rpy="0 0 0" />
      <mass
        value="0.385684351005629" />
      <inertia
        ixx="0.000140770233725746"
        ixy="4.77061098456113E-08"
        ixz="-6.57625183657226E-07"
        iyy="0.000170456017896524"
        iyz="4.83143500058617E-06"
        izz="0.000126959258320037" />
    </inertial>
    <visual>
      <origin
        xyz="0 0 0"
        rpy="0 0 0" />
      <geometry>
        <mesh
          filename="../meshes/l_arm_shoulder_yaw_Link.STL" />
      </geometry>
      <material
        name="">
        <color
          rgba="1 1 1 1" />
      </material>
    </visual>
    <collision>
      <origin
        xyz="0 0 0"
        rpy="0 0 0" />
      <geometry>
        <mesh
          filename="../meshes/l_arm_shoulder_yaw_Link.STL" />
      </geometry>
    </collision>
  </link>
  <joint
    name="l_arm_shoulder_yaw_joint"
    type="fixed">
    <origin
      xyz="0 0 -0.108"
      rpy="0 0 0" />
    <parent
      link="l_arm_shoulder_roll_Link" />
    <child
      link="l_arm_shoulder_yaw_Link" />
    <axis
      xyz="0 0 1" />
    <limit
      lower="-2"
      upper="2"
      effort="36"
      velocity="12" />
  </joint>
  <link
    name="l_arm_elbow_Link">
    <inertial>
      <origin
        xyz="0.000783882641962441 -0.0071164610235743 -0.000187670615894142"
        rpy="0 0 0" />
      <mass
        value="0.0234686345431745" />
      <inertia
        ixx="4.69343397566853E-06"
        ixy="-1.99964708764804E-09"
        ixz="9.87920406079632E-08"
        iyy="9.07836938758881E-06"
        iyz="4.78743667979099E-10"
        izz="5.08242714541202E-06" />
    </inertial>
    <visual>
      <origin
        xyz="0 0 0"
        rpy="0 0 0" />
      <geometry>
        <mesh
          filename="../meshes/l_arm_elbow_Link.STL" />
      </geometry>
      <material
        name="">
        <color
          rgba="1 1 1 1" />
      </material>
    </visual>
    <collision>
      <origin
        xyz="0 0 0"
        rpy="0 0 0" />
      <geometry>
        <mesh
          filename="../meshes/l_arm_elbow_Link.STL" />
      </geometry>
    </collision>
  </link>
  <joint
    name="l_arm_elbow_joint"
    type="fixed">
    <origin
      xyz="0 -0.017 -0.11875"
      rpy="0 0 0" />
    <parent
      link="l_arm_shoulder_yaw_Link" />
    <child
      link="l_arm_elbow_Link" />
    <axis
      xyz="0 1 0" />
    <limit
      lower="-1.5"
      upper="1.5"
      effort="36"
      velocity="12" />
  </joint>
  <link
    name="r_arm_shoulder_pitch_Link">
    <inertial>
      <origin
        xyz="-0.0032277 0.00090287 0.064029"
        rpy="0 0 0" />
      <mass
        value="0.47485" />
      <inertia
        ixx="0.00026491"
        ixy="1.493E-06"
        ixz="-1.3787E-05"
        iyy="0.00023165"
        iyz="4.313E-06"
        izz="0.00018067" />
    </inertial>
    <visual>
      <origin
        xyz="0 0 0"
        rpy="0 0 0" />
      <geometry>
        <mesh
          filename="../meshes/r_arm_shoulder_pitch_Link.STL" />
      </geometry>
      <material
        name="">
        <color
          rgba="0.898039215686275 0.917647058823529 0.929411764705882 1" />
      </material>
    </visual>
    <collision>
      <origin
        xyz="0 0 0"
        rpy="0 0 0" />
      <geometry>
        <mesh
          filename="../meshes/r_arm_shoulder_pitch_Link.STL" />
      </geometry>
    </collision>
  </link>
  <joint
    name="r_arm_shoulder_pitch_joint"
    type="fixed">
    <origin
      xyz="0 -0.16535 0.20168"
      rpy="1.2217 0 0" />
    <parent
      link="base_link" />
    <child
      link="r_arm_shoulder_pitch_Link" />
    <axis
      xyz="0 0 1" />
    <limit
      lower="-2"
      upper="2"
      effort="36"
      velocity="12" />
  </joint>
  <link
    name="r_arm_shoulder_roll_Link">
    <inertial>
      <origin
        xyz="0.00482434461878539 0.000218754304780355 -0.066684892346818"
        rpy="0 0 0" />
      <mass
        value="0.369997353872883" />
      <inertia
        ixx="0.000197558683212289"
        ixy="1.5602634042867E-06"
        ixz="-2.63403084055417E-05"
        iyy="0.00020014685176238"
        iyz="3.03976144077389E-06"
        izz="0.000160207650697516" />
    </inertial>
    <visual>
      <origin
        xyz="0 0 0"
        rpy="0 0 0" />
      <geometry>
        <mesh
          filename="../meshes/r_arm_shoulder_roll_Link.STL" />
      </geometry>
      <material
        name="">
        <color
          rgba="0.780392156862745 0.972549019607843 0.956862745098039 1" />
      </material>
    </visual>
    <collision>
      <origin
        xyz="0 0 0"
        rpy="0 0 0" />
      <geometry>
        <mesh
          filename="../meshes/r_arm_shoulder_roll_Link.STL" />
      </geometry>
    </collision>
  </link>
  <joint
    name="r_arm_shoulder_roll_joint"
    type="fixed">
    <origin
      xyz="0 0 0.07625"
      rpy="-1.2217 0 0" />
    <parent
      link="r_arm_shoulder_pitch_Link" />
    <child
      link="r_arm_shoulder_roll_Link" />
    <axis
      xyz="1 0 0" />
    <limit
      lower="-3"
      upper="0"
      effort="36"
      velocity="12" />
  </joint>
  <link
    name="r_arm_shoulder_yaw_Link">
    <inertial>
      <origin
        xyz="-4.03282683863471E-05 -0.00245809993860069 -0.0964013469128064"
        rpy="0 0 0" />
      <mass
        value="0.385684351005629" />
      <inertia
        ixx="0.000140770233725746"
        ixy="-4.77061098456113E-08"
        ixz="-6.57625183657226E-07"
        iyy="0.000170456017896524"
        iyz="-4.83143500058617E-06"
        izz="0.000126959258320037" />
    </inertial>
    <visual>
      <origin
        xyz="0 0 0"
        rpy="0 0 0" />
      <geometry>
        <mesh
          filename="../meshes/r_arm_shoulder_yaw_Link.STL" />
      </geometry>
      <material
        name="">
        <color
          rgba="1 0.90588 0 1" />
      </material>
    </visual>
    <collision>
      <origin
        xyz="0 0 0"
        rpy="0 0 0" />
      <geometry>
        <mesh
          filename="../meshes/r_arm_shoulder_yaw_Link.STL" />
      </geometry>
    </collision>
  </link>
  <joint
    name="r_arm_shoulder_yaw_joint"
    type="fixed">
    <origin
      xyz="0 0 -0.108"
      rpy="0 0 0" />
    <parent
      link="r_arm_shoulder_roll_Link" />
    <child
      link="r_arm_shoulder_yaw_Link" />
    <axis
      xyz="0 0 1" />
    <limit
      lower="-2"
      upper="2"
      effort="36"
      velocity="12" />
  </joint>
  <link
    name="r_arm_elbow_Link">
    <inertial>
      <origin
        xyz="0.000783882643357436 0.00711646102274963 -0.000187670617232349"
        rpy="0 0 0" />
      <mass
        value="0.0234686345431746" />
      <inertia
        ixx="4.69343397566855E-06"
        ixy="1.99964708702846E-09"
        ixz="9.87920406079816E-08"
        iyy="9.07836938758883E-06"
        iyz="-4.78743642735379E-10"
        izz="5.08242714541201E-06" />
    </inertial>
    <visual>
      <origin
        xyz="0 0 0"
        rpy="0 0 0" />
      <geometry>
        <mesh
          filename="../meshes/r_arm_elbow_Link.STL" />
      </geometry>
      <material
        name="">
        <color
          rgba="0.972549019607843 0.945098039215686 0.780392156862745 1" />
      </material>
    </visual>
    <collision>
      <origin
        xyz="0 0 0"
        rpy="0 0 0" />
      <geometry>
        <mesh
          filename="../meshes/r_arm_elbow_Link.STL" />
      </geometry>
    </collision>
  </link>
  <joint
    name="r_arm_elbow_joint"
    type="fixed">
    <origin
      xyz="0 0.017 -0.11875"
      rpy="0 0 0" />
    <parent
      link="r_arm_shoulder_yaw_Link" />
    <child
      link="r_arm_elbow_Link" />
    <axis
      xyz="0 1 0" />
    <limit
      lower="-1.5"
      upper="1.5"
      effort="36"
      velocity="12" />
  </joint>
  <link
    name="l_leg_hip_roll_Link">
    <inertial>
      <origin
        xyz="0.073997 -2.6118E-05 -0.00038831"
        rpy="0 0 0" />
      <mass
        value="1.2237" />
      <inertia
        ixx="0.0010875"
        ixy="2.5346E-06"
        ixz="4.9227E-06"
        iyy="0.0012014"
        iyz="-2.996E-07"
        izz="0.0021103" />
    </inertial>
    <visual>
      <origin
        xyz="0 0 0"
        rpy="0 0 0" />
      <geometry>
        <mesh
          filename="../meshes/l_leg_hip_roll_Link.STL" />
      </geometry>
      <material
        name="">
        <color
          rgba="0.64706 0.61961 0.58824 1" />
      </material>
    </visual>
    <!-- <collision>
      <origin
        xyz="0 0 0"
        rpy="0 0 0" />
      <geometry>
        <mesh
          filename="../meshes/l_leg_hip_roll_Link.STL" />
      </geometry>
    </collision> -->
  </link>
  <joint
    name="l_leg_hip_roll_joint"
    type="revolute">
    <origin
      xyz="-0.0792 0.09002 -0.085"
      rpy="0 0 0" />
    <parent
      link="base_link" />
    <child
      link="l_leg_hip_roll_Link" />
    <axis
      xyz="1 0 0" />
    <limit
      lower="-0.3"
      upper="1"
      effort="90"
      velocity="12" />
  </joint>
  <link
    name="l_leg_hip_yaw_Link">
    <inertial>
      <origin
        xyz="0.00018298 -0.018275 -0.069994"
        rpy="0 0 0" />
      <mass
        value="1.5439" />
      <inertia
        ixx="0.0016181"
        ixy="1.229E-06"
        ixz="-2.3738E-06"
        iyy="0.0028764"
        iyz="2.6967E-06"
        izz="0.0014519" />
    </inertial>
    <visual>
      <origin
        xyz="0 0 0"
        rpy="0 0 0" />
      <geometry>
        <mesh
          filename="../meshes/l_leg_hip_yaw_Link.STL" />
      </geometry>
      <material
        name="">
        <color
          rgba="0.89804 0.91765 0.92941 1" />
      </material>
    </visual>
    <collision>
      <origin
        xyz="0 0 0"
        rpy="0 0 0" />
      <geometry>
        <mesh
          filename="../meshes/l_leg_hip_yaw_Link.STL" />
      </geometry>
    </collision>
  </link>
  <joint
    name="l_leg_hip_yaw_joint"
    type="revolute">
    <origin
      xyz="0.0815 0 -0.0375"
      rpy="0 0 0" />
    <parent
      link="l_leg_hip_roll_Link" />
    <child
      link="l_leg_hip_yaw_Link" />
    <axis
      xyz="0 0 1" />
    <limit
      lower="-0.75"
      upper="1.05"
      effort="90"
      velocity="12" />
  </joint>
  <link
    name="l_leg_hip_pitch_Link">
    <inertial>
      <origin
        xyz="0.00263050346808996 0.0505924691116392 -0.0509281264870309"
        rpy="0 0 0" />
      <mass
        value="2.63780166885626" />
      <inertia
        ixx="0.0128050639410327"
        ixy="-7.30670824907572E-06"
        ixz="0.00012322434413997"
        iyy="0.0146659167630542"
        iyz="0.000182392843008207"
        izz="0.00218142025359868" />
    </inertial>
    <visual>
      <origin
        xyz="0 0 0"
        rpy="0 0 0" />
      <geometry>
        <mesh
          filename="../meshes/l_leg_hip_pitch_Link.STL" />
      </geometry>
      <material
        name="">
        <color
          rgba="1 1 1 1" />
      </material>
    </visual>
    <collision>
      <origin
        xyz="0 0 0"
        rpy="0 0 0" />
      <geometry>
        <mesh
          filename="../meshes/l_leg_hip_pitch_Link.STL" />
      </geometry>
    </collision>
  </link>
  <joint
    name="l_leg_hip_pitch_joint"
    type="revolute">
    <origin
      xyz="0 0 -0.076"
      rpy="0 -0.2 0" />
    <parent
      link="l_leg_hip_yaw_Link" />
    <child
      link="l_leg_hip_pitch_Link" />
    <axis
      xyz="0 1 0" />
    <limit
      lower="-1.12"
      upper="0.88"
      effort="150"
      velocity="12" />
  </joint>
  <link
    name="l_leg_knee_Link">
    <inertial>
      <origin
        xyz="0.0026677 0.0022197 -0.12804"
        rpy="0 0 0" />
      <mass
        value="1.3457" />
      <inertia
        ixx="0.0022506"
        ixy="-2.3667E-06"
        ixz="-2.2148E-05"
        iyy="0.0022436"
        iyz="-4.5481E-05"
        izz="0.00046377" />
    </inertial>
    <visual>
      <origin
        xyz="0 0 0"
        rpy="0 0 0" />
      <geometry>
        <mesh
          filename="../meshes/l_leg_knee_Link.STL" />
      </geometry>
      <material
        name="">
        <color
          rgba="1 1 1 1" />
      </material>
    </visual>
    <collision>
      <origin
        xyz="0 0 0"
        rpy="0 0 0" />
      <geometry>
        <mesh
          filename="../meshes/l_leg_knee_Link.STL" />
      </geometry>
    </collision>
  </link>
  <joint
    name="l_leg_knee_joint"
    type="revolute">
    <origin
      xyz="0 0.032659 -0.27"
      rpy="0 0.4 0" />
    <parent
      link="l_leg_hip_pitch_Link" />
    <child
      link="l_leg_knee_Link" />
    <axis
      xyz="0 1 0" />
    <limit
      lower="-0.28"
      upper="1.6"
      effort="150"
      velocity="12" />
  </joint>
  <link
    name="l_leg_ankle_pitch_Link">
    <inertial>
      <origin
        xyz="0.0010416 3.8669E-09 -9.735E-10"
        rpy="0 0 0" />
      <mass
        value="0.089954" />
      <inertia
        ixx="1.1624E-05"
        ixy="6.8819E-12"
        ixz="-6.205E-13"
        iyy="1.4297E-05"
        iyz="7.1496E-13"
        izz="2.1929E-05" />
    </inertial>
    <visual>
      <origin
        xyz="0 0 0"
        rpy="0 0 0" />
      <geometry>
        <mesh
          filename="../meshes/l_leg_ankle_pitch_Link.STL" />
      </geometry>
      <material
        name="">
        <color
          rgba="1 1 1 1" />
      </material>
    </visual>
    <!-- <collision>
      <origin
        xyz="0 0 0"
        rpy="0 0 0" />
      <geometry>
        <mesh
          filename="../meshes/l_leg_ankle_pitch_Link.STL" />
      </geometry>
    </collision> -->
  </link>
  <joint
    name="l_leg_ankle_pitch_joint"
    type="revolute">
    <origin
      xyz="0 0 -0.28"
      rpy="0 -0.2 0" />
    <parent
      link="l_leg_knee_Link" />
    <child
      link="l_leg_ankle_pitch_Link" />
    <axis
      xyz="0 1 0" />
    <limit
      lower="-0.48"
      upper="0.88"
      effort="27"
      velocity="12" />
  </joint>
  <link
    name="l_leg_ankle_roll_Link">
    <inertial>
      <origin
        xyz="0.0095635 2.5209E-05 -0.027782"
        rpy="0 0 0" />
      <mass
        value="0.85800" />
      <inertia
        ixx="0.003694"
        ixy="0.000000"
        ixz="-0.001493"
        iyy="0.006904"
        iyz="0.000000"
        izz="0.004640" />
    </inertial>
    <visual>
      <origin
        xyz="0 0 0"
        rpy="0 0 0" />
      <geometry>
        <mesh
          filename="../meshes/l_leg_ankle_roll_with_shoes_Link.STL" />
      </geometry>
      <material
        name="">
        <color
          rgba="1 1 1 1" />
      </material>
    </visual>

    <collision>
      <origin
        xyz="0 0 0"
        rpy="0 0 0" />
      <geometry>
        <mesh
          filename="../meshes/l_leg_ankle_roll_with_shoes_Link.STL" />
      </geometry>
    </collision>
  </link>
  <joint
    name="l_leg_ankle_roll_joint"
    type="revolute">
    <origin
      xyz="0 0 0"
      rpy="0 0 0" />
    <parent
      link="l_leg_ankle_pitch_Link" />
    <child
      link="l_leg_ankle_roll_Link" />
    <axis
      xyz="1 0 0" />
    <limit
      lower="-0.5"
      upper="0.5"
      effort="27"
      velocity="12" />
  </joint>
  <link
    name="r_leg_hip_roll_Link">
    <inertial>
      <origin
        xyz="0.073997 -2.6118E-05 -0.00038831"
        rpy="0 0 0" />
      <mass
        value="1.2237" />
      <inertia
        ixx="0.0010875"
        ixy="2.5346E-06"
        ixz="4.9227E-06"
        iyy="0.0012014"
        iyz="-2.996E-07"
        izz="0.0021103" />
    </inertial>
    <visual>
      <origin
        xyz="0 0 0"
        rpy="0 0 0" />
      <geometry>
        <mesh
          filename="../meshes/r_leg_hip_roll_Link.STL" />
      </geometry>
      <material
        name="">
        <color
          rgba="0.49804 0.49804 0.49804 1" />
      </material>
    </visual>
    <!-- <collision>
      <origin
        xyz="0 0 0"
        rpy="0 0 0" />
      <geometry>
        <mesh
          filename="../meshes/r_leg_hip_roll_Link.STL" />
      </geometry>
    </collision> -->
  </link>
  <joint
    name="r_leg_hip_roll_joint"
    type="revolute">
    <origin
      xyz="-0.0792 -0.09002 -0.085"
      rpy="0 0 0" />
    <parent
      link="base_link" />
    <child
      link="r_leg_hip_roll_Link" />
    <axis
      xyz="1 0 0" />
    <limit
      lower="-1"
      upper="0.3"
      effort="90"
      velocity="12" />
  </joint>
  <link
    name="r_leg_hip_yaw_Link">
    <inertial>
      <origin
        xyz="0.00018298 0.018275 -0.069994"
        rpy="0 0 0" />
      <mass
        value="1.5439" />
      <inertia
        ixx="0.0016181"
        ixy="1.229E-06"
        ixz="-2.3738E-06"
        iyy="0.0028764"
        iyz="-2.6967E-06"
        izz="0.0014519" />
    </inertial>
    <visual>
      <origin
        xyz="0 0 0"
        rpy="0 0 0" />
      <geometry>
        <mesh
          filename="../meshes/r_leg_hip_yaw_Link.STL" />
      </geometry>
      <material
        name="">
        <color
          rgba="0.89804 0.91765 0.92941 1" />
      </material>
    </visual>
    <collision>
      <origin
        xyz="0 0 0"
        rpy="0 0 0" />
      <geometry>
        <mesh
          filename="../meshes/r_leg_hip_yaw_Link.STL" />
      </geometry>
    </collision>
  </link>
  <joint
    name="r_leg_hip_yaw_joint"
    type="revolute">
    <origin
      xyz="0.0815 0 -0.0375"
      rpy="0 0 0" />
    <parent
      link="r_leg_hip_roll_Link" />
    <child
      link="r_leg_hip_yaw_Link" />
    <axis
      xyz="0 0 1" />
    <limit
      lower="-1.05"
      upper="0.75"
      effort="90"
      velocity="12" />
  </joint>
  <link
    name="r_leg_hip_pitch_Link">
    <inertial>
      <origin
        xyz="0.00263050346808996 -0.0505924691116392 -0.0509281264870309"
        rpy="0 0 0" />
      <mass
        value="2.63780166885626" />
      <inertia
        ixx="0.0128050639410327"
        ixy="-7.30670824907572E-06"
        ixz="0.00012322434413997"
        iyy="0.0146659167630542"
        iyz="0.000182392843008207"
        izz="0.00218142025359868" />
    </inertial>
    <visual>
      <origin
        xyz="0 0 0"
        rpy="0 0 0" />
      <geometry>
        <mesh
          filename="../meshes/r_leg_hip_pitch_Link.STL" />
      </geometry>
      <material
        name="">
        <color
          rgba="0.89804 0.91765 0.92941 1" />
      </material>
    </visual>
    <collision>
      <origin
        xyz="0 0 0"
        rpy="0 0 0" />
      <geometry>
        <mesh
          filename="../meshes/r_leg_hip_pitch_Link.STL" />
      </geometry>
    </collision>
  </link>
  <joint
    name="r_leg_hip_pitch_joint"
    type="revolute">
    <origin
      xyz="0 0 -0.076"
      rpy="0 -0.2 0" />
    <parent
      link="r_leg_hip_yaw_Link" />
    <child
      link="r_leg_hip_pitch_Link" />
    <axis
      xyz="0 1 0" />
    <limit
      lower="-1.12"
      upper="0.88"
      effort="150"
      velocity="12" />
  </joint>
  <link
    name="r_leg_knee_Link">
    <inertial>
      <origin
        xyz="0.0026677 -0.0022197 -0.12804"
        rpy="0 0 0" />
      <mass
        value="1.3457" />
      <inertia
        ixx="0.0022506"
        ixy="2.3667E-06"
        ixz="-2.2148E-05"
        iyy="0.0022436"
        iyz="4.5481E-05"
        izz="0.00046377" />
    </inertial>
    <visual>
      <origin
        xyz="0 0 0"
        rpy="0 0 0" />
      <geometry>
        <mesh
          filename="../meshes/r_leg_knee_Link.STL" />
      </geometry>
      <material
        name="">
        <color
          rgba="0.89804 0.91765 0.92941 1" />
      </material>
    </visual>
    <collision>
      <origin
        xyz="0 0 0"
        rpy="0 0 0" />
      <geometry>
        <mesh
          filename="../meshes/r_leg_knee_Link.STL" />
      </geometry>
    </collision>
  </link>
  <joint
    name="r_leg_knee_joint"
    type="revolute">
    <origin
      xyz="0 -0.032659 -0.27"
      rpy="0 0.4 0" />
    <parent
      link="r_leg_hip_pitch_Link" />
    <child
      link="r_leg_knee_Link" />
    <axis
      xyz="0 1 0" />
    <limit
      lower="-0.28"
      upper="1.6"
      effort="150"
      velocity="12" />
  </joint>
  <link
    name="r_leg_ankle_pitch_Link">
    <inertial>
      <origin
        xyz="0.0010416 -3.8669E-09 -9.735E-10"
        rpy="0 0 0" />
      <mass
        value="0.089954" />
      <inertia
        ixx="1.1624E-05"
        ixy="-6.8819E-12"
        ixz="-6.205E-13"
        iyy="1.4297E-05"
        iyz="-7.1496E-13"
        izz="2.1929E-05" />
    </inertial>
    <visual>
      <origin
        xyz="0 0 0"
        rpy="0 0 0" />
      <geometry>
        <mesh
          filename="../meshes/r_leg_ankle_pitch_Link.STL" />
      </geometry>
      <material
        name="">
        <color
          rgba="0.64706 0.61961 0.58824 1" />
      </material>
    </visual>
    <!-- <collision>
      <origin
        xyz="0 0 0"
        rpy="0 0 0" />
      <geometry>
        <mesh
          filename="../meshes/r_leg_ankle_pitch_Link.STL" />
      </geometry>
    </collision> -->
  </link>
  <joint
    name="r_leg_ankle_pitch_joint"
    type="revolute">
    <origin
      xyz="0 0 -0.28"
      rpy="0 -0.2 0" />
    <parent
      link="r_leg_knee_Link" />
    <child
      link="r_leg_ankle_pitch_Link" />
    <axis
      xyz="0 1 0" />
    <limit
      lower="-0.48"
      upper="0.88"
      effort="27"
      velocity="12" />
  </joint>
  <link
    name="r_leg_ankle_roll_Link">
    <inertial>
      <origin
        xyz="0.0095635 -2.5209E-05 -0.027782"
        rpy="0 0 0" />
      <mass
        value="0.85800" />
        <!-- Ixx = 0.003694 Ixy = 0.000000 Ixz = -0.001493
        Iyx = 0.000000 Iyy = 0.006904 Iyz = 0.000000
        Izx = -0.001493 Izy = 0.000000 Izz = 0.004640 -->
      <inertia
        ixx="0.003694"
        ixy="0.000000"
        ixz="-0.001493"
        iyy="0.006904"
        iyz="0.000000"
        izz="0.004640" />
    </inertial>
    <visual>
      <origin
        xyz="0 0 0"
        rpy="0 0 0" />
      <geometry>
        <mesh
          filename="../meshes/r_leg_ankle_roll_with_shoes_Link.STL" />
      </geometry>
      <material
        name="">
        <color
          rgba="0.89804 0.91765 0.92941 1" />
      </material>
    </visual>

    <collision>
      <origin
        xyz="0 0 0"
        rpy="0 0 0" />
      <geometry>
        <mesh
          filename="../meshes/r_leg_ankle_roll_with_shoes_Link.STL" />
      </geometry>
    </collision>


  </link>
  <joint
    name="r_leg_ankle_roll_joint"
    type="revolute">
    <origin
      xyz="0 0 0"
      rpy="0 0 0" />
    <parent
      link="r_leg_ankle_pitch_Link" />
    <child
      link="r_leg_ankle_roll_Link" />
    <axis
      xyz="1 0 0" />
    <limit
      lower="-0.5"
      upper="0.5"
      effort="27"
      velocity="12" />
  </joint>
</robot>
